<?xml version="1.0"?>
<robot name="worm">
    <!-- Base Link -->
    <link name="worm_link_0">
        <visual>
            <geometry>
                <box size="0.08 0.03 0.03"/>
            </geometry>
            <material name="blue">
                <color rgba="0 0 0.8 1"/>
            </material>
            <origin xyz="0 0 0" rpy="0 0 0"/>
        </visual>
        <collision>
            <geometry>
                <box size="0.08 0.03 0.03"/>
            </geometry>
            <origin xyz="0 0 0" rpy="0 0 0"/>
        </collision>
        <inertial>
            <mass value="0.1"/>
            <origin xyz="0 0 0" rpy="0 0 0"/>
            <inertia ixx="0.0001" ixy="0" ixz="0" iyy="0.0001" iyz="0" izz="0.0001"/>
        </inertial>
    </link>

    <!-- Segment 1 -->
    <link name="worm_link_1">
        <visual>
            <geometry>
                <box size="0.08 0.03 0.03"/>
            </geometry>
            <material name="blue1">
                <color rgba="0 0.2 0.8 1"/>
            </material>
            <origin xyz="0 0 0" rpy="0 0 0"/>
        </visual>
        <collision>
            <geometry>
                <box size="0.08 0.03 0.03"/>
            </geometry>
            <origin xyz="0 0 0" rpy="0 0 0"/>
        </collision>
        <inertial>
            <mass value="0.1"/>
            <origin xyz="0 0 0" rpy="0 0 0"/>
            <inertia ixx="0.0001" ixy="0" ixz="0" iyy="0.0001" iyz="0" izz="0.0001"/>
        </inertial>
    </link>

    <!-- Segment 2 -->
    <link name="worm_link_2">
        <visual>
            <geometry>
                <box size="0.08 0.03 0.03"/>
            </geometry>
            <material name="blue2">
                <color rgba="0 0.4 0.8 1"/>
            </material>
            <origin xyz="0 0 0" rpy="0 0 0"/>
        </visual>
        <collision>
            <geometry>
                <box size="0.08 0.03 0.03"/>
            </geometry>
            <origin xyz="0 0 0" rpy="0 0 0"/>
        </collision>
        <inertial>
            <mass value="0.1"/>
            <origin xyz="0 0 0" rpy="0 0 0"/>
            <inertia ixx="0.0001" ixy="0" ixz="0" iyy="0.0001" iyz="0" izz="0.0001"/>
        </inertial>
    </link>

    <!-- Segment 3 -->
    <link name="worm_link_3">
        <visual>
            <geometry>
                <box size="0.08 0.03 0.03"/>
            </geometry>
            <material name="blue3">
                <color rgba="0 0.6 0.8 1"/>
            </material>
            <origin xyz="0 0 0" rpy="0 0 0"/>
        </visual>
        <collision>
            <geometry>
                <box size="0.08 0.03 0.03"/>
            </geometry>
            <origin xyz="0 0 0" rpy="0 0 0"/>
        </collision>
        <inertial>
            <mass value="0.1"/>
            <origin xyz="0 0 0" rpy="0 0 0"/>
            <inertia ixx="0.0001" ixy="0" ixz="0" iyy="0.0001" iyz="0" izz="0.0001"/>
        </inertial>
    </link>

    <!-- Segment 4 -->
    <link name="worm_link_4">
        <visual>
            <geometry>
                <box size="0.08 0.03 0.03"/>
            </geometry>
            <material name="blue4">
                <color rgba="0 0.8 0.8 1"/>
            </material>
            <origin xyz="0 0 0" rpy="0 0 0"/>
        </visual>
        <collision>
            <geometry>
                <box size="0.08 0.03 0.03"/>
            </geometry>
            <origin xyz="0 0 0" rpy="0 0 0"/>
        </collision>
        <inertial>
            <mass value="0.1"/>
            <origin xyz="0 0 0" rpy="0 0 0"/>
            <inertia ixx="0.0001" ixy="0" ixz="0" iyy="0.0001" iyz="0" izz="0.0001"/>
        </inertial>
    </link>

    <!-- Segment 5 (Head) -->
    <link name="worm_link_5">
        <visual>
            <geometry>
                <box size="0.08 0.03 0.03"/>
            </geometry>
            <material name="blue5">
                <color rgba="0 1.0 0.8 1"/>
            </material>
            <origin xyz="0 0 0" rpy="0 0 0"/>
        </visual>
        <collision>
            <geometry>
                <box size="0.08 0.03 0.03"/>
            </geometry>
            <origin xyz="0 0 0" rpy="0 0 0"/>
        </collision>
        <inertial>
            <mass value="0.1"/>
            <origin xyz="0 0 0" rpy="0 0 0"/>
            <inertia ixx="0.0001" ixy="0" ixz="0" iyy="0.0001" iyz="0" izz="0.0001"/>
        </inertial>
    </link>

    <!-- Joint 0-1 -->
    <joint name="worm_joint_0" type="revolute">
        <parent link="worm_link_0"/>
        <child link="worm_link_1"/>
        <origin rpy="0 0 0" xyz="0.08 0 0"/>
        <axis xyz="0 1 0"/>
        <limit effort="5.0" lower="-1.0" upper="1.0" velocity="3.0"/>
        <dynamics damping="0.1" friction="0.1"/>
    </joint>

    <!-- Joint 1-2 -->
    <joint name="worm_joint_1" type="revolute">
        <parent link="worm_link_1"/>
        <child link="worm_link_2"/>
        <origin rpy="0 0 0" xyz="0.08 0 0"/>
        <axis xyz="0 1 0"/>
        <limit effort="5.0" lower="-1.0" upper="1.0" velocity="3.0"/>
        <dynamics damping="0.1" friction="0.1"/>
    </joint>

    <!-- Joint 2-3 -->
    <joint name="worm_joint_2" type="revolute">
        <parent link="worm_link_2"/>
        <child link="worm_link_3"/>
        <origin rpy="0 0 0" xyz="0.08 0 0"/>
        <axis xyz="0 1 0"/>
        <limit effort="5.0" lower="-1.0" upper="1.0" velocity="3.0"/>
        <dynamics damping="0.1" friction="0.1"/>
    </joint>

    <!-- Joint 3-4 -->
    <joint name="worm_joint_3" type="revolute">
        <parent link="worm_link_3"/>
        <child link="worm_link_4"/>
        <origin rpy="0 0 0" xyz="0.08 0 0"/>
        <axis xyz="0 1 0"/>
        <limit effort="5.0" lower="-1.0" upper="1.0" velocity="3.0"/>
        <dynamics damping="0.1" friction="0.1"/>
    </joint>

    <!-- Joint 4-5 -->
    <joint name="worm_joint_4" type="revolute">
        <parent link="worm_link_4"/>
        <child link="worm_link_5"/>
        <origin rpy="0 0 0" xyz="0.08 0 0"/>
        <axis xyz="0 1 0"/>
        <limit effort="5.0" lower="-1.0" upper="1.0" velocity="3.0"/>
        <dynamics damping="0.1" friction="0.1"/>
    </joint>
</robot> 